Workbook

Sheet Config
A1: Setting | B1: Value | C1: Notes | D1: Holidays (optional)
A2: Start date | B2: 46307 | C2: Đổi ngày bắt đầu; nghỉ cuối tuần
A3: Member 1 | B3: mem1 | C3: Đổi tên tại đây
A4: Member 2 | B4: mem2 | C4: Đổi tên tại đây
A5: PM | B5: PM | C5: Người review/ghi comment
A6: API_Gate | B6: NOT_APPROVED | C6: PM duyệt sau khi API có evidence
A7: Capacity hours/day | B7: 6 | C7: Giả định mỗi người
A8: Working days | B8: 20 | C8: Khung một tháng
A9: Scope | B9: MVP only | C9: v1.3; local UI user-authorized before gate; PM NOT_APPROVED

Sheet Tasks
A1: ID | B1: Module | C1: Phase | D1: Task | E1: Owner | F1: Reviewer | G1: Start day | H1: End day | I1: Start date | J1: Due date | K1: Hours | L1: Dependencies | M1: Deliverable | N1: Acceptance | O1: Finish? | P1: Status | Q1: Ready / Blocked | R1: PM Comment | S1: Evidence / PR | T1: Actual Finish | U1: Dev Note
A2: A01 | B2: Nền tảng | C2: API | D2: Thiết lập project Django, custom User và quy ước API | E2: =Config!$B$3 | F2: =Config!$B$4 | G2: 1 | H2: 1 | I2: =WORKDAY(Config!$B$2-1,G2,Config!$D$2:$D$30) | J2: =WORKDAY(Config!$B$2-1,H2,Config!$D$2:$D$30) | K2: 5 | M2: manage.py; config; accounts/models.py; requirements.txt | N2: Django check/migrate chạy trên DB rỗng; không dùng User mặc định rồi đổi sau | O2: FALSE | P2: =IF(OR(O2=TRUE,O2="TRUE"),"finish","unfinish") | Q2: =IF(OR(O2=TRUE,O2="TRUE"),"done",IF(TRUE,"ready","blocked"))
A3: B01 | B3: Hợp đồng module | C3: API | D3: Chốt v1.3 schema/vision/source VISION và migration chéo | E3: =Config!$B$4 | F3: =Config!$B$3 | G3: 1 | H3: 1 | I3: =WORKDAY(Config!$B$2-1,G3,Config!$D$2:$D$30) | J3: =WORKDAY(Config!$B$2-1,H3,Config!$D$2:$D$30) | K3: 5 | M3: docs/api-contract.md; core/enums.py | N3: mem1/mem2 phối hợp scope/mẫu private, vision contract và migration; QR giữ lịch sử, gate NOT_APPROVED | O3: FALSE | P3: =IF(OR(O3=TRUE,O3="TRUE"),"finish","unfinish") | Q3: =IF(OR(O3=TRUE,O3="TRUE"),"done",IF(TRUE,"ready","blocked"))
A4: A02 | B4: M01 Tài khoản | C4: API | D4: API login/logout/me và cấp tài khoản tối thiểu | E4: =Config!$B$3 | F4: =Config!$B$4 | G4: 2 | H4: 2 | I4: =WORKDAY(Config!$B$2-1,G4,Config!$D$2:$D$30) | J4: =WORKDAY(Config!$B$2-1,H4,Config!$D$2:$D$30) | K4: 6 | L4: A01, B01 | M4: accounts/views.py; services.py; urls.py | N4: Đăng nhập 3 vai trò; STUDENT chỉ bản thân; logout thu hồi phiên; CSRF đúng | O4: FALSE | P4: =IF(OR(O4=TRUE,O4="TRUE"),"finish","unfinish") | Q4: =IF(OR(O4=TRUE,O4="TRUE"),"done",IF(AND(COUNTIFS($A$2:$A$41,"A01",$P$2:$P$41,"finish")=1,COUNTIFS($A$2:$A$41,"B01",$P$2:$P$41,"finish")=1),"ready","blocked"))
A5: B02 | B5: M04 Lịch | C5: API | D5: Đặc tả lịch tuần, session và snapshot; viết ca kiểm chứng | E5: =Config!$B$4 | F5: =Config!$B$3 | G5: 2 | H5: 2 | I5: =WORKDAY(Config!$B$2-1,G5,Config!$D$2:$D$30) | J5: =WORKDAY(Config!$B$2-1,H5,Config!$D$2:$D$30) | K5: 4 | L5: B01 | M5: schedules/README.md; tests/test_schedules.py | N5: Có ca sáng/chiều, sơ mi/thể dục, mở buổi lặp; chưa phụ thuộc migration lớp | O5: FALSE | P5: =IF(OR(O5=TRUE,O5="TRUE"),"finish","unfinish") | Q5: =IF(OR(O5=TRUE,O5="TRUE"),"done",IF(AND(COUNTIFS($A$2:$A$41,"B01",$P$2:$P$41,"finish")=1),"ready","blocked"))
A6: A03 | B6: M02 Khối/lớp | C6: API | D6: Model và API khối, lớp, gán một GVCN | E6: =Config!$B$3 | F6: =Config!$B$4 | G6: 3 | H6: 3 | I6: =WORKDAY(Config!$B$2-1,G6,Config!$D$2:$D$30) | J6: =WORKDAY(Config!$B$2-1,H6,Config!$D$2:$D$30) | K6: 6 | L6: A02 | M6: academics/models.py; services.py; views.py | N6: Một lớp một GVCN; giám thị quản lý tất cả; giáo viên chỉ lớp được giao | O6: FALSE | P6: =IF(OR(O6=TRUE,O6="TRUE"),"finish","unfinish") | Q6: =IF(OR(O6=TRUE,O6="TRUE"),"done",IF(AND(COUNTIFS($A$2:$A$41,"A02",$P$2:$P$41,"finish")=1),"ready","blocked"))
A7: B03 | B7: M04 Lịch | C7: API | D7: Chốt đầu vào/đầu ra lịch với model lớp/học sinh | E7: =Config!$B$4 | F7: =Config!$B$3 | G7: 3 | H7: 3 | I7: =WORKDAY(Config!$B$2-1,G7,Config!$D$2:$D$30) | J7: =WORKDAY(Config!$B$2-1,H7,Config!$D$2:$D$30) | K7: 4 | L7: B02 | M7: docs/api-contract.md; schedules/forms.py | N7: Có class_id, weekday, slot, start_time, grace_minutes, uniform_type; không thêm module ngoài MVP | O7: FALSE | P7: =IF(OR(O7=TRUE,O7="TRUE"),"finish","unfinish") | Q7: =IF(OR(O7=TRUE,O7="TRUE"),"done",IF(AND(COUNTIFS($A$2:$A$41,"B02",$P$2:$P$41,"finish")=1),"ready","blocked"))
A8: A04 | B8: M03 Học sinh | C8: API | D8: Model học sinh và API thêm/xem theo lớp | E8: =Config!$B$3 | F8: =Config!$B$4 | G8: 4 | H8: 4 | I8: =WORKDAY(Config!$B$2-1,G8,Config!$D$2:$D$30) | J8: =WORKDAY(Config!$B$2-1,H8,Config!$D$2:$D$30) | K8: 5 | L8: A03 | M8: students/models.py; services.py; views.py | N8: Họ tên, mã, lớp/khối; trùng tên được, trùng mã bị chặn; lớp ngoài quyền trả 403/404 | O8: FALSE | P8: =IF(OR(O8=TRUE,O8="TRUE"),"finish","unfinish") | Q8: =IF(OR(O8=TRUE,O8="TRUE"),"done",IF(AND(COUNTIFS($A$2:$A$41,"A03",$P$2:$P$41,"finish")=1),"ready","blocked"))
A9: B04 | B9: M04 Lịch | C9: API | D9: Model và API lịch tuần theo lớp | E9: =Config!$B$4 | F9: =Config!$B$3 | G9: 4 | H9: 4 | I9: =WORKDAY(Config!$B$2-1,G9,Config!$D$2:$D$30) | J9: =WORKDAY(Config!$B$2-1,H9,Config!$D$2:$D$30) | K9: 6 | L9: A03, B03 | M9: schedules/models.py; services.py; views.py | N9: Lưu giờ vào học và SHIRT/SPORTS; không có hai rule trùng thứ/slot/lớp | O9: FALSE | P9: =IF(OR(O9=TRUE,O9="TRUE"),"finish","unfinish") | Q9: =IF(OR(O9=TRUE,O9="TRUE"),"done",IF(AND(COUNTIFS($A$2:$A$41,"A03",$P$2:$P$41,"finish")=1,COUNTIFS($A$2:$A$41,"B03",$P$2:$P$41,"finish")=1),"ready","blocked"))
A10: A05 | B10: M03 Học sinh | C10: API | D10: API cập nhật, tìm kiếm và tài khoản học sinh theo session | E10: =Config!$B$3 | F10: =Config!$B$4 | G10: 5 | H10: 5 | I10: =WORKDAY(Config!$B$2-1,G10,Config!$D$2:$D$30) | J10: =WORKDAY(Config!$B$2-1,H10,Config!$D$2:$D$30) | K10: 6 | L10: A04 | M10: students/forms.py; accounts/services.py | N10: Sửa đúng phạm vi; student user liên kết một hồ sơ; không trả mật khẩu trong danh sách | O10: FALSE | P10: =IF(OR(O10=TRUE,O10="TRUE"),"finish","unfinish") | Q10: =IF(OR(O10=TRUE,O10="TRUE"),"done",IF(AND(COUNTIFS($A$2:$A$41,"A04",$P$2:$P$41,"finish")=1),"ready","blocked"))
A11: B05 | B11: M04 Buổi học | C11: API | D11: Tạo buổi từ lịch theo ngày, lấy danh sách học sinh snapshot | E11: =Config!$B$4 | F11: =Config!$B$3 | G11: 5 | H11: 5 | I11: =WORKDAY(Config!$B$2-1,G11,Config!$D$2:$D$30) | J11: =WORKDAY(Config!$B$2-1,H11,Config!$D$2:$D$30) | K11: 6 | L11: A04, B04 | M11: schedules/services.py; models.py | N11: Unique lớp/ngày/buổi; roster lấy học sinh active; sửa lịch không đổi snapshot buổi đã mở | O11: FALSE | P11: =IF(OR(O11=TRUE,O11="TRUE"),"finish","unfinish") | Q11: =IF(OR(O11=TRUE,O11="TRUE"),"done",IF(AND(COUNTIFS($A$2:$A$41,"A04",$P$2:$P$41,"finish")=1,COUNTIFS($A$2:$A$41,"B04",$P$2:$P$41,"finish")=1),"ready","blocked"))
A12: A06 | B12: M03 Ảnh | C12: API | D12: Ảnh private và review enrollment metadata/scope học sinh | E12: =Config!$B$3 | F12: =Config!$B$4 | G12: 6 | H12: 6 | I12: =WORKDAY(Config!$B$2-1,G12,Config!$D$2:$D$30) | J12: =WORKDAY(Config!$B$2-1,H12,Config!$D$2:$D$30) | K12: 6 | L12: A05 | M12: students/services.py; views.py; core/storage.py | N12: Ảnh profile private; không tự enroll; sample GET không bytes, staff scope và DELETE/re-enroll làm proposal cũ vô hiệu | O12: FALSE | P12: =IF(OR(O12=TRUE,O12="TRUE"),"finish","unfinish") | Q12: =IF(OR(O12=TRUE,O12="TRUE"),"done",IF(AND(COUNTIFS($A$2:$A$41,"A05",$P$2:$P$41,"finish")=1),"ready","blocked"))
A13: B06 | B13: M04 Buổi học | C13: API | D13: API mở/chốt buổi tối thiểu và tạo attendance UNMARKED | E13: =Config!$B$4 | F13: =Config!$B$3 | G13: 6 | H13: 6 | I13: =WORKDAY(Config!$B$2-1,G13,Config!$D$2:$D$30) | J13: =WORKDAY(Config!$B$2-1,H13,Config!$D$2:$D$30) | K13: 5 | L13: B05, A05 | M13: schedules/services.py; attendance/models.py | N13: Mở lặp không nhân đôi; chốt có cảnh báo chưa ghi nhận; chốt giữ NOT_CHECKED | O13: FALSE | P13: =IF(OR(O13=TRUE,O13="TRUE"),"finish","unfinish") | Q13: =IF(OR(O13=TRUE,O13="TRUE"),"done",IF(AND(COUNTIFS($A$2:$A$41,"B05",$P$2:$P$41,"finish")=1,COUNTIFS($A$2:$A$41,"A05",$P$2:$P$41,"finish")=1),"ready","blocked"))
A14: A07 | B14: M01–M03 Quyền | C14: API | D14: Kiểm chứng quyền tài khoản, lớp, học sinh và ảnh | E14: =Config!$B$3 | F14: =Config!$B$4 | G14: 7 | H14: 7 | I14: =WORKDAY(Config!$B$2-1,G14,Config!$D$2:$D$30) | J14: =WORKDAY(Config!$B$2-1,H14,Config!$D$2:$D$30) | K14: 5 | L14: A06, A03 | M14: tests/test_permissions.py; test_students.py | N14: Teacher A không đọc/sửa/tải ảnh lớp B; student không đọc roster; supervisor được toàn trường | O14: FALSE | P14: =IF(OR(O14=TRUE,O14="TRUE"),"finish","unfinish") | Q14: =IF(OR(O14=TRUE,O14="TRUE"),"done",IF(AND(COUNTIFS($A$2:$A$41,"A06",$P$2:$P$41,"finish")=1,COUNTIFS($A$2:$A$41,"A03",$P$2:$P$41,"finish")=1),"ready","blocked"))
A15: B07 | B15: M05 Điểm danh | C15: API | D15: API roster, điểm danh thủ công/vắng và thời gian đến | E15: =Config!$B$4 | F15: =Config!$B$3 | G15: 7 | H15: 7 | I15: =WORKDAY(Config!$B$2-1,G15,Config!$D$2:$D$30) | J15: =WORKDAY(Config!$B$2-1,H15,Config!$D$2:$D$30) | K15: 6 | L15: B06 | M15: attendance/services.py; views.py; forms.py | N15: PRESENT có arrived_at; đúng giờ/muộn theo server và snapshot; vắng không có giờ đến | O15: FALSE | P15: =IF(OR(O15=TRUE,O15="TRUE"),"finish","unfinish") | Q15: =IF(OR(O15=TRUE,O15="TRUE"),"done",IF(AND(COUNTIFS($A$2:$A$41,"B06",$P$2:$P$41,"finish")=1),"ready","blocked"))
A16: A08 | B16: M07 Báo cáo | C16: API | D16: Viết query báo cáo bằng fixture, công thức tổng hợp | E16: =Config!$B$3 | F16: =Config!$B$4 | G16: 8 | H16: 8 | I16: =WORKDAY(Config!$B$2-1,G16,Config!$D$2:$D$30) | J16: =WORKDAY(Config!$B$2-1,H16,Config!$D$2:$D$30) | K16: 5 | L16: B06, A07 | M16: reports/queries.py; tests/test_reports.py | N16: Phân biệt có mặt/vắng/chưa ghi nhận; không đếm buổi chưa mở; quyền lớp được lọc ở query | O16: FALSE | P16: =IF(OR(O16=TRUE,O16="TRUE"),"finish","unfinish") | Q16: =IF(OR(O16=TRUE,O16="TRUE"),"done",IF(AND(COUNTIFS($A$2:$A$41,"B06",$P$2:$P$41,"finish")=1,COUNTIFS($A$2:$A$41,"A07",$P$2:$P$41,"finish")=1),"ready","blocked"))
A17: B08 | B17: M05 Điểm danh | C17: API | D17: Version, unique, retry chống điểm danh trùng và lỗi mạng | E17: =Config!$B$4 | F17: =Config!$B$3 | G17: 8 | H17: 8 | I17: =WORKDAY(Config!$B$2-1,G17,Config!$D$2:$D$30) | J17: =WORKDAY(Config!$B$2-1,H17,Config!$D$2:$D$30) | K17: 5 | L17: B07 | M17: attendance/services.py; core/idempotency.py; tests/test_attendance.py | N17: Retry cùng key không nhân đôi; 07:05:00 đúng giờ, 07:05:01 muộn; không báo lưu thành công nếu lỗi | O17: FALSE | P17: =IF(OR(O17=TRUE,O17="TRUE"),"finish","unfinish") | Q17: =IF(OR(O17=TRUE,O17="TRUE"),"done",IF(AND(COUNTIFS($A$2:$A$41,"B07",$P$2:$P$41,"finish")=1),"ready","blocked"))
A18: A09 | B18: M07 Báo cáo | C18: API | D18: API báo cáo chi tiết/tổng hợp, lọc ngày/lớp/khối | E18: =Config!$B$3 | F18: =Config!$B$4 | G18: 9 | H18: 9 | I18: =WORKDAY(Config!$B$2-1,G18,Config!$D$2:$D$30) | J18: =WORKDAY(Config!$B$2-1,H18,Config!$D$2:$D$30) | K18: 5 | L18: A08, B08 | M18: reports/views.py; forms.py; urls.py | N18: Bộ lọc ngoài quyền bị chặn; tổng đúng với dữ liệu attendance thực; mẫu số 0 hiển thị rõ | O18: FALSE | P18: =IF(OR(O18=TRUE,O18="TRUE"),"finish","unfinish") | Q18: =IF(OR(O18=TRUE,O18="TRUE"),"done",IF(AND(COUNTIFS($A$2:$A$41,"A08",$P$2:$P$41,"finish")=1,COUNTIFS($A$2:$A$41,"B08",$P$2:$P$41,"finish")=1),"ready","blocked"))
A19: B09 | B19: M05 Vision | C19: API | D19: Engine Haar/LBPH/HSV và đăng ký mẫu private | E19: =Config!$B$4 | F19: =Config!$B$3 | G19: 9 | H19: 9 | I19: =WORKDAY(Config!$B$2-1,G19,Config!$D$2:$D$30) | J19: =WORKDAY(Config!$B$2-1,H19,Config!$D$2:$D$30) | K19: 6 | L19: B08, A05 | M19: vision/engine.py; models; enrollment API; tests/test_vision_engine.py | N19: 3–10 ảnh thay nguyên tử,128x128 private; LBPH match/unknown/ambiguous; HSV UNKNOWN khi thiếu vùng áo; không cam kết accuracy | O19: FALSE | P19: =IF(OR(O19=TRUE,O19="TRUE"),"finish","unfinish") | Q19: =IF(OR(O19=TRUE,O19="TRUE"),"done",IF(AND(COUNTIFS($A$2:$A$41,"B08",$P$2:$P$41,"finish")=1,COUNTIFS($A$2:$A$41,"A05",$P$2:$P$41,"finish")=1),"ready","blocked"))
A20: A10 | B20: M07 Xuất XLSX | C20: API | D20: Xuất Excel chi tiết/tổng hợp bằng openpyxl | E20: =Config!$B$3 | F20: =Config!$B$4 | G20: 10 | H20: 10 | I20: =WORKDAY(Config!$B$2-1,G20,Config!$D$2:$D$30) | J20: =WORKDAY(Config!$B$2-1,H20,Config!$D$2:$D$30) | K20: 6 | L20: A09 | M20: reports/exporters.py; services.py | N20: Tối đa 5.000 dòng, đúng bộ lọc/quyền; không chạy formula do nội dung người dùng | O20: FALSE | P20: =IF(OR(O20=TRUE,O20="TRUE"),"finish","unfinish") | Q20: =IF(OR(O20=TRUE,O20="TRUE"),"done",IF(AND(COUNTIFS($A$2:$A$41,"A09",$P$2:$P$41,"finish")=1),"ready","blocked"))
A21: B10 | B21: M05 Vision | C21: API | D21: API staff phân tích một ảnh theo roster và queue proposal | E21: =Config!$B$4 | F21: =Config!$B$3 | G21: 10 | H21: 10 | I21: =WORKDAY(Config!$B$2-1,G21,Config!$D$2:$D$30) | J21: =WORKDAY(Config!$B$2-1,H21,Config!$D$2:$D$30) | K21: 6 | L21: B09 | M21: vision scan POST/GET; tests/test_vision_api.py | N21: staff scope; STUDENT403; single image2MiB/4MP; roster50;20/phút; PENDING không PRESENT; expiry120s; Idempotency-Key | O21: FALSE | P21: =IF(OR(O21=TRUE,O21="TRUE"),"finish","unfinish") | Q21: =IF(OR(O21=TRUE,O21="TRUE"),"done",IF(AND(COUNTIFS($A$2:$A$41,"B09",$P$2:$P$41,"finish")=1),"ready","blocked"))
A22: A11 | B22: M07 Xuất CSV | C22: API | D22: CSV UTF-8 BOM, endpoint download và metadata | E22: =Config!$B$3 | F22: =Config!$B$4 | G22: 11 | H22: 11 | I22: =WORKDAY(Config!$B$2-1,G22,Config!$D$2:$D$30) | J22: =WORKDAY(Config!$B$2-1,H22,Config!$D$2:$D$30) | K22: 5 | L22: A10 | M22: reports/exporters.py; views.py; core/storage.py | N22: Đúng dấu tiếng Việt/timezone; tải kiểm tra quyền; XLSX và CSV đối soát cùng dữ liệu | O22: FALSE | P22: =IF(OR(O22=TRUE,O22="TRUE"),"finish","unfinish") | Q22: =IF(OR(O22=TRUE,O22="TRUE"),"done",IF(AND(COUNTIFS($A$2:$A$41,"A10",$P$2:$P$41,"finish")=1),"ready","blocked"))
A23: B11 | B23: M05 Vision xác minh | C23: API | D23: API confirm/reject proposal và manual fallback | E23: =Config!$B$4 | F23: =Config!$B$3 | G23: 11 | H23: 11 | I23: =WORKDAY(Config!$B$2-1,G23,Config!$D$2:$D$30) | J23: =WORKDAY(Config!$B$2-1,H23,Config!$D$2:$D$30) | K23: 6 | L23: B10 | M23: vision/services.py; confirm/reject; attendance source migration | N23: identity_confirmed bắt buộc; scan/attendance version, sample revision, OPEN/time; retry; manual/close/transfer/re-enroll/delete vô hiệu proposal | O23: FALSE | P23: =IF(OR(O23=TRUE,O23="TRUE"),"finish","unfinish") | Q23: =IF(OR(O23=TRUE,O23="TRUE"),"done",IF(AND(COUNTIFS($A$2:$A$41,"B10",$P$2:$P$41,"finish")=1),"ready","blocked"))
A24: A12 | B24: M07 Báo cáo | C24: API | D24: Đối soát report VISION/manual và đồng phục | E24: =Config!$B$3 | F24: =Config!$B$4 | G24: 12 | H24: 12 | I24: =WORKDAY(Config!$B$2-1,G24,Config!$D$2:$D$30) | J24: =WORKDAY(Config!$B$2-1,H24,Config!$D$2:$D$30) | K24: 6 | L24: A11, B11 | M24: tests/test_report_reconciliation.py; reports/queries.py | N24: PENDING không PRESENT; VISION arrived_at=scanned_at; JSON/XLSX/CSV khớp; QR chỉ lịch sử | O24: FALSE | P24: =IF(OR(O24=TRUE,O24="TRUE"),"finish","unfinish") | Q24: =IF(OR(O24=TRUE,O24="TRUE"),"done",IF(AND(COUNTIFS($A$2:$A$41,"A11",$P$2:$P$41,"finish")=1,COUNTIFS($A$2:$A$41,"B11",$P$2:$P$41,"finish")=1),"ready","blocked"))
A25: B12 | B25: M06 Đồng phục | C25: API | D25: Uniform staff quyết định và confirm vision nguyên tử | E25: =Config!$B$4 | F25: =Config!$B$3 | G25: 12 | H25: 12 | I25: =WORKDAY(Config!$B$2-1,G25,Config!$D$2:$D$30) | J25: =WORKDAY(Config!$B$2-1,H25,Config!$D$2:$D$30) | K25: 6 | L25: B11 | M25: attendance/uniform_rules.py; forms.py; services.py | N25: HSV chỉ gợi ý; UNKNOWN không tự đạt/vi phạm; invalid uniform rollback cả confirm/attendance/log | O25: FALSE | P25: =IF(OR(O25=TRUE,O25="TRUE"),"finish","unfinish") | Q25: =IF(OR(O25=TRUE,O25="TRUE"),"done",IF(AND(COUNTIFS($A$2:$A$41,"B11",$P$2:$P$41,"finish")=1),"ready","blocked"))
A26: A13 | B26: Tích hợp API | C26: API | D26: Kiểm chứng quyền xuyên suốt và tải file/ảnh | E26: =Config!$B$3 | F26: =Config!$B$4 | G26: 13 | H26: 13 | I26: =WORKDAY(Config!$B$2-1,G26,Config!$D$2:$D$30) | J26: =WORKDAY(Config!$B$2-1,H26,Config!$D$2:$D$30) | K26: 6 | L26: A12, B12 | M26: tests/test_api_permissions.py; test_reports.py | N26: Học sinh không xuất data; giáo viên xuất lớp mình; đổi ID không vượt quyền; trường bắt buộc validate | O26: FALSE | P26: =IF(OR(O26=TRUE,O26="TRUE"),"finish","unfinish") | Q26: =IF(OR(O26=TRUE,O26="TRUE"),"done",IF(AND(COUNTIFS($A$2:$A$41,"A12",$P$2:$P$41,"finish")=1,COUNTIFS($A$2:$A$41,"B12",$P$2:$P$41,"finish")=1),"ready","blocked"))
A27: B13 | B27: Tích hợp API | C27: API | D27: Kiểm chứng vision→staff confirm→uniform→close | E27: =Config!$B$4 | F27: =Config!$B$3 | G27: 13 | H27: 13 | I27: =WORKDAY(Config!$B$2-1,G27,Config!$D$2:$D$30) | J27: =WORKDAY(Config!$B$2-1,H27,Config!$D$2:$D$30) | K27: 6 | L27: B12 | M27: tests/test_full_flow.py; test_qr.py | N27: Mẫu/ảnh/scope/version/expiry/retry; manual fallback; QR mặc định tắt; migrate mới và nâng cấp | O27: FALSE | P27: =IF(OR(O27=TRUE,O27="TRUE"),"finish","unfinish") | Q27: =IF(OR(O27=TRUE,O27="TRUE"),"done",IF(AND(COUNTIFS($A$2:$A$41,"B12",$P$2:$P$41,"finish")=1),"ready","blocked"))
A28: A14 | B28: API docs/seed | C28: API | D28: Dữ liệu giả và request collection cho PM nghiệm thu | E28: =Config!$B$3 | F28: =Config!$B$4 | G28: 14 | H28: 14 | I28: =WORKDAY(Config!$B$2-1,G28,Config!$D$2:$D$30) | J28: =WORKDAY(Config!$B$2-1,H28,Config!$D$2:$D$30) | K28: 5 | L28: A13 | M28: management command seed_demo; docs/api-contract.md; api-requests.http | N28: 2 lớp/20 học sinh giả, tài khoản các vai trò; PM gọi API không cần giao diện | O28: FALSE | P28: =IF(OR(O28=TRUE,O28="TRUE"),"finish","unfinish") | Q28: =IF(OR(O28=TRUE,O28="TRUE"),"done",IF(AND(COUNTIFS($A$2:$A$41,"A13",$P$2:$P$41,"finish")=1),"ready","blocked"))
A29: B14 | B29: API hoàn thiện | C29: API | D29: Sửa lỗi vision và viết hướng dẫn demo OpenCV | E29: =Config!$B$4 | F29: =Config!$B$3 | G29: 14 | H29: 14 | I29: =WORKDAY(Config!$B$2-1,G29,Config!$D$2:$D$30) | J29: =WORKDAY(Config!$B$2-1,H29,Config!$D$2:$D$30) | K29: 5 | L29: B13 | M29: docs/huong-dan-demo-opencv.md; api-requests.http; evidence | N29: Setup/enrollment/API/presentation5–7phút; synthetic không chứng minh camera/accuracy/liveness | O29: FALSE | P29: =IF(OR(O29=TRUE,O29="TRUE"),"finish","unfinish") | Q29: =IF(OR(O29=TRUE,O29="TRUE"),"done",IF(AND(COUNTIFS($A$2:$A$41,"B13",$P$2:$P$41,"finish")=1),"ready","blocked"))
A30: A15 | B30: API gate | C30: API | D30: Review API gate với PM: auth/lớp/học sinh/report/export | E30: =Config!$B$3 | F30: =Config!$B$5 | G30: 15 | H30: 15 | I30: =WORKDAY(Config!$B$2-1,G30,Config!$D$2:$D$30) | J30: =WORKDAY(Config!$B$2-1,H30,Config!$D$2:$D$30) | K30: 4 | L30: A14, B14 | M30: docs/api-acceptance.md; link evidence | N30: PM có test result, collection và file export; chưa mở frontend khi còn lỗi chặn luồng | O30: FALSE | P30: =IF(OR(O30=TRUE,O30="TRUE"),"finish","unfinish") | Q30: =IF(OR(O30=TRUE,O30="TRUE"),"done",IF(AND(COUNTIFS($A$2:$A$41,"A14",$P$2:$P$41,"finish")=1,COUNTIFS($A$2:$A$41,"B14",$P$2:$P$41,"finish")=1),"ready","blocked"))
A31: B15 | B31: API gate | C31: API | D31: PM review API gate lịch/attendance/vision/uniform | E31: =Config!$B$4 | F31: =Config!$B$5 | G31: 15 | H31: 15 | I31: =WORKDAY(Config!$B$2-1,G31,Config!$D$2:$D$30) | J31: =WORKDAY(Config!$B$2-1,H31,Config!$D$2:$D$30) | K31: 4 | L31: B14, A14 | M31: docs/api-acceptance.md; link evidence | N31: PM đọc evidence mới và giới hạn camera/HSV; không dùng126test QR cũ; gate NOT_APPROVED cho tới quyết định PM | O31: FALSE | P31: =IF(OR(O31=TRUE,O31="TRUE"),"finish","unfinish") | Q31: =IF(OR(O31=TRUE,O31="TRUE"),"done",IF(AND(COUNTIFS($A$2:$A$41,"B14",$P$2:$P$41,"finish")=1,COUNTIFS($A$2:$A$41,"A14",$P$2:$P$41,"finish")=1),"ready","blocked"))
A32: A16 | B32: UI M01–M03 | C32: FRONTEND_LATER | D32: Sau API gate: giao diện đăng nhập, lớp và học sinh tối thiểu | E32: =Config!$B$3 | F32: =Config!$B$4 | G32: 16 | H32: 16 | I32: =WORKDAY(Config!$B$2-1,G32,Config!$D$2:$D$30) | J32: =WORKDAY(Config!$B$2-1,H32,Config!$D$2:$D$30) | K32: 5 | L32: A15, B15 | M32: Tạo frontend Django Templates sau PM duyệt | N32: Dùng API/service đã ổn định; không tạo frontend ở giai đoạn hiện tại | O32: FALSE | P32: =IF(OR(O32=TRUE,O32="TRUE"),"finish","unfinish") | Q32: =IF(OR(O32=TRUE,O32="TRUE"),"done",IF(AND(COUNTIFS($A$2:$A$41,"A15",$P$2:$P$41,"finish")=1,COUNTIFS($A$2:$A$41,"B15",$P$2:$P$41,"finish")=1,Config!$B$6="APPROVED",COUNTIFS($C$2:$C$41,"API",$P$2:$P$41,"unfinish")=0,COUNTIF($C$2:$C$41,"API")>0),"ready","blocked"))
A33: B16 | B33: UI M04–M05 | C33: FRONTEND_LATER | D33: Sau API gate: giao diện lịch và danh sách điểm danh | E33: =Config!$B$4 | F33: =Config!$B$3 | G33: 16 | H33: 16 | I33: =WORKDAY(Config!$B$2-1,G33,Config!$D$2:$D$30) | J33: =WORKDAY(Config!$B$2-1,H33,Config!$D$2:$D$30) | K33: 5 | L33: A15, B15 | M33: Tạo frontend Django Templates sau PM duyệt | N33: Hiển thị trạng thái và giờ từ server; không tính quyền/thời gian ở client | O33: FALSE | P33: =IF(OR(O33=TRUE,O33="TRUE"),"finish","unfinish") | Q33: =IF(OR(O33=TRUE,O33="TRUE"),"done",IF(AND(COUNTIFS($A$2:$A$41,"A15",$P$2:$P$41,"finish")=1,COUNTIFS($A$2:$A$41,"B15",$P$2:$P$41,"finish")=1,Config!$B$6="APPROVED",COUNTIFS($C$2:$C$41,"API",$P$2:$P$41,"unfinish")=0,COUNTIF($C$2:$C$41,"API")>0),"ready","blocked"))
A34: A17 | B34: UI M03/M07 | C34: FRONTEND_LATER | D34: Sau API gate: upload ảnh, bộ lọc báo cáo và xuất file | E34: =Config!$B$3 | F34: =Config!$B$4 | G34: 17 | H34: 17 | I34: =WORKDAY(Config!$B$2-1,G34,Config!$D$2:$D$30) | J34: =WORKDAY(Config!$B$2-1,H34,Config!$D$2:$D$30) | K34: 6 | L34: A16 | M34: Templates học sinh/báo cáo sau PM duyệt | N34: Upload lỗi giữ ảnh cũ; đúng quyền lớp; xuất được XLSX/CSV | O34: FALSE | P34: =IF(OR(O34=TRUE,O34="TRUE"),"finish","unfinish") | Q34: =IF(OR(O34=TRUE,O34="TRUE"),"done",IF(AND(COUNTIFS($A$2:$A$41,"A16",$P$2:$P$41,"finish")=1,Config!$B$6="APPROVED",COUNTIFS($C$2:$C$41,"API",$P$2:$P$41,"unfinish")=0,COUNTIF($C$2:$C$41,"API")>0),"ready","blocked"))
A35: B17 | B35: UI Vision | C35: FRONTEND_LATER | D35: Sau API gate: camera chụp ảnh, gợi ý và queue vision | E35: =Config!$B$4 | F35: =Config!$B$3 | G35: 17 | H35: 17 | I35: =WORKDAY(Config!$B$2-1,G35,Config!$D$2:$D$30) | J35: =WORKDAY(Config!$B$2-1,H35,Config!$D$2:$D$30) | K35: 6 | L35: B16 | M35: Templates/JavaScript vision sau PM duyệt | N35: Chỉ sau gate; staff xác nhận bắt buộc, lỗi/từ chối camera có manual fallback; không tự PRESENT | O35: FALSE | P35: =IF(OR(O35=TRUE,O35="TRUE"),"finish","unfinish") | Q35: =IF(OR(O35=TRUE,O35="TRUE"),"done",IF(AND(COUNTIFS($A$2:$A$41,"B16",$P$2:$P$41,"finish")=1,Config!$B$6="APPROVED",COUNTIFS($C$2:$C$41,"API",$P$2:$P$41,"unfinish")=0,COUNTIF($C$2:$C$41,"API")>0),"ready","blocked"))
A36: A18 | B36: UI M07 hoàn thiện | C36: FRONTEND_LATER | D36: Sau API gate: tổng hợp báo cáo, lỗi và trạng thái đang lưu | E36: =Config!$B$3 | F36: =Config!$B$4 | G36: 18 | H36: 18 | I36: =WORKDAY(Config!$B$2-1,G36,Config!$D$2:$D$30) | J36: =WORKDAY(Config!$B$2-1,H36,Config!$D$2:$D$30) | K36: 5 | L36: A17 | M36: Templates báo cáo/học sinh sau PM duyệt | N36: Tổng khớp API; lỗi không báo thành công; mã/tên/lớp rõ | O36: FALSE | P36: =IF(OR(O36=TRUE,O36="TRUE"),"finish","unfinish") | Q36: =IF(OR(O36=TRUE,O36="TRUE"),"done",IF(AND(COUNTIFS($A$2:$A$41,"A17",$P$2:$P$41,"finish")=1,Config!$B$6="APPROVED",COUNTIFS($C$2:$C$41,"API",$P$2:$P$41,"unfinish")=0,COUNTIF($C$2:$C$41,"API")>0),"ready","blocked"))
A37: B18 | B37: UI M06 hoàn thiện | C37: FRONTEND_LATER | D37: Sau API gate: xác minh và đồng phục cùng form, chốt buổi | E37: =Config!$B$4 | F37: =Config!$B$3 | G37: 18 | H37: 18 | I37: =WORKDAY(Config!$B$2-1,G37,Config!$D$2:$D$30) | J37: =WORKDAY(Config!$B$2-1,H37,Config!$D$2:$D$30) | K37: 5 | L37: B17 | M37: Templates xác minh/đồng phục sau PM duyệt | N37: Không mặc định đạt; chốt cảnh báo pending/chưa ghi nhận; giữ NOT_CHECKED | O37: FALSE | P37: =IF(OR(O37=TRUE,O37="TRUE"),"finish","unfinish") | Q37: =IF(OR(O37=TRUE,O37="TRUE"),"done",IF(AND(COUNTIFS($A$2:$A$41,"B17",$P$2:$P$41,"finish")=1,Config!$B$6="APPROVED",COUNTIFS($C$2:$C$41,"API",$P$2:$P$41,"unfinish")=0,COUNTIF($C$2:$C$41,"API")>0),"ready","blocked"))
A38: A19 | B38: Nghiệm thu MVP | C38: QA | D38: Kiểm chứng luồng thật và quyền/report trên dữ liệu giả | E38: =Config!$B$3 | F38: =Config!$B$5 | G38: 19 | H38: 19 | I38: =WORKDAY(Config!$B$2-1,G38,Config!$D$2:$D$30) | J38: =WORKDAY(Config!$B$2-1,H38,Config!$D$2:$D$30) | K38: 6 | L38: A18, B18 | M38: docs/mvp-acceptance.md; evidence | N38: Teacher/supervisor/student chạy đúng quyền; số liệu/file khớp; PM ghi comment từng lỗi | O38: FALSE | P38: =IF(OR(O38=TRUE,O38="TRUE"),"finish","unfinish") | Q38: =IF(OR(O38=TRUE,O38="TRUE"),"done",IF(AND(COUNTIFS($A$2:$A$41,"A18",$P$2:$P$41,"finish")=1,COUNTIFS($A$2:$A$41,"B18",$P$2:$P$41,"finish")=1,Config!$B$6="APPROVED",COUNTIFS($C$2:$C$41,"API",$P$2:$P$41,"unfinish")=0,COUNTIF($C$2:$C$41,"API")>0),"ready","blocked"))
A39: B19 | B39: Nghiệm thu MVP | C39: QA | D39: Kiểm chứng thiết bị OpenCV, đồng phục và fallback | E39: =Config!$B$4 | F39: =Config!$B$5 | G39: 19 | H39: 19 | I39: =WORKDAY(Config!$B$2-1,G39,Config!$D$2:$D$30) | J39: =WORKDAY(Config!$B$2-1,H39,Config!$D$2:$D$30) | K39: 6 | L39: A18, B18 | M39: docs/mvp-acceptance.md; evidence | N39: Camera thật/quyền/mạng/retry, mặt lạ/mờ/nhiều người, áo bị che; log riêng enrollment/evaluation; không cam kết chống ảnh giả | O39: FALSE | P39: =IF(OR(O39=TRUE,O39="TRUE"),"finish","unfinish") | Q39: =IF(OR(O39=TRUE,O39="TRUE"),"done",IF(AND(COUNTIFS($A$2:$A$41,"A18",$P$2:$P$41,"finish")=1,COUNTIFS($A$2:$A$41,"B18",$P$2:$P$41,"finish")=1,Config!$B$6="APPROVED",COUNTIFS($C$2:$C$41,"API",$P$2:$P$41,"unfinish")=0,COUNTIF($C$2:$C$41,"API")>0),"ready","blocked"))
A40: A20 | B40: Bàn giao | C40: QA | D40: Sửa lỗi còn lại, README setup và kịch bản thi | E40: =Config!$B$3 | F40: =Config!$B$5 | G40: 20 | H40: 20 | I40: =WORKDAY(Config!$B$2-1,G40,Config!$D$2:$D$30) | J40: =WORKDAY(Config!$B$2-1,H40,Config!$D$2:$D$30) | K40: 4 | L40: A19, B19 | M40: README.md; docs/demo-script.md; evidence | N40: Setup từ máy sạch theo README; migrations/seed/test có hướng dẫn; PM duyệt bàn giao | O40: FALSE | P40: =IF(OR(O40=TRUE,O40="TRUE"),"finish","unfinish") | Q40: =IF(OR(O40=TRUE,O40="TRUE"),"done",IF(AND(COUNTIFS($A$2:$A$41,"A19",$P$2:$P$41,"finish")=1,COUNTIFS($A$2:$A$41,"B19",$P$2:$P$41,"finish")=1,Config!$B$6="APPROVED",COUNTIFS($C$2:$C$41,"API",$P$2:$P$41,"unfinish")=0,COUNTIF($C$2:$C$41,"API")>0),"ready","blocked"))
...

Sheet Dashboard
A1: Metric | B1: Value
A2: Total tasks | B2: =COUNTA(Tasks!A2:A41)
A3: Finish | B3: =COUNTIF(Tasks!P2:P41,"finish")
A4: Unfinish | B4: =COUNTIF(Tasks!P2:P41,"unfinish")
A5: Overall progress | B5: =IFERROR(B3/B2,0)
A6: API tasks | B6: =COUNTIF(Tasks!C2:C41,"API")
A7: API finish | B7: =COUNTIFS(Tasks!C2:C41,"API",Tasks!P2:P41,"finish")
A8: API progress | B8: =IFERROR(B7/B6,0)
A9: Frontend planned | B9: =COUNTIF(Tasks!C2:C41,"FRONTEND_LATER")
A10: API_Gate | B10: =Config!B6
A11: Frontend unlocked | B11: =IF(AND(B7=B6,B6>0,Config!B6="APPROVED"),"YES","NO")
A12: Owner | B12: Progress
A13: =Config!B3 | B13: =IFERROR(COUNTIFS(Tasks!E2:E41,A13,Tasks!P2:P41,"finish")/COUNTIF(Tasks!E2:E41,A13),0)
A14: =Config!B4 | B14: =IFERROR(COUNTIFS(Tasks!E2:E41,A14,Tasks!P2:P41,"finish")/COUNTIF(Tasks!E2:E41,A14),0)
A15: mem1 planned hours | B15: =SUMIF(Tasks!E2:E41,Config!B3,Tasks!K2:K41)
A16: mem2 planned hours | B16: =SUMIF(Tasks!E2:E41,Config!B4,Tasks!K2:K41)
A17: Note | B17: Tick finish after tests/review/evidence; PM decides API gate.

Sheet Modules
A1: Module | B1: Owner | C1: Scope
A2: Accounts | B2: =Config!B3 | C2: Auth/session/role/scope
A3: Academics | B3: =Config!B3 | C3: Grade/class/one homeroom teacher
A4: Students | B4: =Config!B3 | C4: Profile/class/private photo
A5: Reports | B5: =Config!B3 | C5: Scoped summaries/XLSX/CSV
A6: Schedules | B6: =Config!B4 | C6: Weekly rules/session/roster snapshot
A7: Attendance / Uniform | B7: =Config!B4 | C7: Arrival/manual/verification/uniform/close
A8: Vision / QR legacy | B8: =Config!B4 | C8: OpenCV staff confirm; QR disabled by default
